Workbook
Name _Toc257106251: Guidance!$A$1
Name _Toc257106252: Guidance!#REF!
Name Data: #REF!
Name Data: #REF!
Name Data: #REF!
Name Data: #REF!
Name Data: #REF!
Name Data: #REF!
Name HR1_formula: 'HR1'!$X$12:$AW$26
Name HR1_formula: #REF!
Name HR2_formula: 'HR2'!$AF$11:$BH$66
Name HR2_formula: 'HR3'!$AD$11:$BF$49
Name HR2_formula: 'HR4'!$AD$11:$BF$49
Name HR2_formula: 'HR5'!$AD$11:$BF$31
Name HR2_formula: #REF!
Name HR3_formula: #REF!
Name HR4_formula: #REF!
Name HR4_formula: #REF!
Name HR5_formula: #REF!

Sheet Cover
A6: 2025_26
A7: Operational Statistics Collection
A8: Human resources (HR)
A10: North West Fire Control
A11: =VLOOKUP(B250,B251:D316,3,FALSE) -> NWFC
A13: Index of Tables | B13: Description
A14: HR1 | B14: Staff strength by rank and contract type (full time equivalent)
A15: HR2 | B15: Wholetime firefighters by gender identity, age, disability, ethnicity, religion and sexual orientation (headcount)
A16: HR3 | B16: On call firefighters by gender identity, age, disability, ethnicity, religion and sexual orientation (headcount)
A17: HR4 | B17: Fire Control personnel by gender identity, age, disability, ethnicity, religion and sexual orientation (headcount)
A18: HR5 | B18: Support Staff by gender identity, age, disability, ethnicity, religion and sexual orientation (headcount)
A19: HR6 | B19: New joiners by gender identity, age and ethnicity (headcount)
A20: HR7 | B20: Number of apprentices by gender identity, ethnicity and age (headcount)
A21: Guidance | B21: Guidance notes
A23: QA checks
A24: Following data entry please review the QA checks on the right hand side / below the cells in which data has been inputted. Where possible, please resolve any highlighted issues and provide explanatory commentary where necessary.
A26: Please complete by Friday 1 May 2026 and send the spreadsheet as an attachment via e-mail to firestatistics@communities.gov.uk
A28: Contact
A29: E-mail Address
A31: If you have any comments on the data submitted please provide them in the box below. If not, please leave blank.
A250: FRS Selector>>>>> | B250: 45 | C250: =MAX(B251:B316) -> 45
B251: 1 | C251: Avon | D251: E31000001
B252: 2 | C252: Bedfordshire | D252: E31000002
B253: 3 | C253: Berkshire | D253: E31000003
B254: 4 | C254: Buckinghamshire | D254: E31000004
B255: 5 | C255: Cambridgeshire | D255: E31000005
B256: 6 | C256: Cheshire | D256: E31000006
B257: 7 | C257: Cleveland | D257: E31000007
B258: 8 | C258: Cornwall | D258: E31000008
B259: 9 | C259: Cumbria | D259: E31000009
B260: 10 | C260: Derbyshire | D260: E31000010
B261: 11 | C261: Devon and Somerset | D261: E31000011
B262: 12 | C262: Dorset and Wiltshire | D262: E31000047
... B295: 45 | C295: North West Fire Control | D295: NWFC
B316: 0 | C316: Template FRS | D316: 0
B319: 2023_24 | C319: 2023 | D319: 2022/23
B320: 2024_25 | C320: 2024 | D320: 2023/24
B321: 2025_26 | C321: 2025 | D321: 2024/25
B322: 2026_27 | C322: 2026 | D322: 2025/26
B323: 2027_28 | C323: 2027 | D323: 2026/27
...

Sheet Guidance
A1: Guidance notes for the completion of the Human Resources Forms (HR1-7)
A3: The HR returns (HR1-H7) collect information on:
A4: > Staff numbers by role and rank
A5: > Number of staff by protected characteristics, covering gender, age, ethnicity, religion, disability, and sexual orientation of FRS staff
A6: > Number of new staff joining FRSs by role
A7: > Number of apprentices employed by FRSs
A9: Information from these returns is used to:
A10: > Monitor the FRS workforce size, including number of new joiners and apprentices
A11: > Monitor the equality and diversity in the Fire and Rescue Service, as per the Department's statutory duty to promote equality across its areas of responsibility under the Equalities Act
A12: > Produce quality-assured figures of numbers of staff for trends both locally and nationally.
A13: > Model workforce composition
A15: The collections on joiners and apprentices are used to:
... A21: Definitions
A22: FRS staff: | B22: FRS staff include personnel employed directly by the Fire and Rescue Authorities across all duty systems. The returns should include:
B23: > All staff on permanent contracts at 31 March 2026
B24: > New temporary and fixed-term staff at 31 March 2026 are to be counted in the temporary or fixed term role held on that day
B25: > Secondees at 31 March 2026 and the FRS is paying their salaries
B26: > Paid apprentices at 31 March 2026
B27: Personnel to be excluded are:
B28: > Agency staff employed for less that a year at 31 March 2026
B29: > Casual staff employed for less than a year at 31 March 2026
B30: > Personnel employed by outside contractors
B31: > Secondees at 31 March 2026 if the FRS is not paying their salaries
B32: > Volunteers
B33: Staff who are on temporary promotion at 31 March 2026 are to be counted in the temporary role held on that day.
B34: Personnel who are over normal retirement age and are still employed by the FRS should be included in the annual returns.
B35: Anyone with 2 contracts of employment should be counted twice in the returns. For example, if a member of staff is employed with a retained and wholetime contract they should be recorded in both the retained duty system and wholetime tables.
A37: Full-time equivalent: | B37: Full-time officers and staff are counted as 1.0, and part-time are counted according to the proportion of full-time worked (for example, a firefighter working 60 per cent of full-time hours is counted as 0.6).
A38: 24-hour units of cover: | B38: Retained firefighters respond, when required, during their ‘on-call’ hours. Therefore, it is more appropriate to calculate their employment in 24-hours of cover, to determine whether this cover is sufficient to fulfil operational commitments.
B39: A single 24 hour unit of cover is equivalent to 120 hours a week. Therefore, a person providing 96 hours of cover a week is 0.8 of a post, 90 hours is 0.75 and 60 hours 0.5.
B40: However, staff might not be employed for an entire hour. Units should be calculated as a percentage of the time spent on call:
B41: Full hours = 1 unit
B42: 45 minutes = 0.75 units
B43: 30 minutes = 0.5 units
B44: 15 minutes = 0.25 units
B45: For example, if a firefighter was employed for 2 hours and 15 minutes, the number of units should be calculated as follows:
B46: 2 units at 100% (full hour) = 2
B47: 1 units at 0.25% (quarter of an hour) = 0.25
A48: Headcount: | B48: Actual total physical number of people employed by the FRS
A49: Brigade Manager: | B49: Includes Chief Fire Officer (CFO), Deputy Chief Fire Officer (DCFO) and Assistant Chief Fire Officer (ACFO). Brigade managers will take charge of incidents of 10 pumps or more.
...

Sheet HR1 - PY data
A1: SHEET | B1: CALENDAR_YEAR | C1: FRS_NAME | D1: ROLE | E1: RANK | F1: TOTAL

Sheet HR1 PY
C4: HR1 | D4: =VLOOKUP(Cover!A6,Cover!B319:D335,2,FALSE) -> 2025 | E4: =Cover!A10 -> North West Fire Control
B11: Wholetime firefighters | C11: On call firefighters | D11: On call firefighters (separate contract) | E11: On call firefighters (part of wholetime contract) | F11: Fire Control
A12: Brigade Manager | B12: {=SUMPRODUCT(('HR1 - PY data'!$A$2:$A$49915=$C$4)*('HR1 - PY data'!$B$2:$B$49915=$D$4)*('HR1 - PY data'!$C$2:$C$49915=$E$4)*('HR1 - PY data'!$D$2:$D$49915=B$11)*('HR1 - PY data'!$E$2:$E$49915=$A12)*('HR1 - PY data'!$F$2:$F49915))} -> 0
A13: Area Manager | B13: {=SUMPRODUCT(('HR1 - PY data'!$A$2:$A$49915=$C$4)*('HR1 - PY data'!$B$2:$B$49915=$D$4)*('HR1 - PY data'!$C$2:$C$49915=$E$4)*('HR1 - PY data'!$D$2:$D$49915=B$11)*('HR1 - PY data'!$E$2:$E$49915=$A13)*('HR1 - PY data'!$F$2:$F49915))} -> 0
A14: Group Manager | B14: {=SUMPRODUCT(('HR1 - PY data'!$A$2:$A$49915=$C$4)*('HR1 - PY data'!$B$2:$B$49915=$D$4)*('HR1 - PY data'!$C$2:$C$49915=$E$4)*('HR1 - PY data'!$D$2:$D$49915=B$11)*('HR1 - PY data'!$E$2:$E$49915=$A14)*('HR1 - PY data'!$F$2:$F49915))} -> 0 | C14: {=SUMPRODUCT(('HR1 - PY data'!$A$2:$A$49915=$C$4)*('HR1 - PY data'!$B$2:$B$49915=$D$4)*('HR1 - PY data'!$C$2:$C$49915=$E$4)*('HR1 - PY data'!$D$2:$D$49915=C$11)*('HR1 - PY data'!$E$2:$E$49915=$A14)*('HR1 - PY data'!$F$2:$F49915))} -> 0 | D14: {=SUMPRODUCT(('HR1 - PY data'!$A$2:$A$49915=$C$4)*('HR1 - PY data'!$B$2:$B$49915=$D$4)*('HR1 - PY data'!$C$2:$C$49915=$E$4)*('HR1 - PY data'!$D$2:$D$49915=D$11)*('HR1 - PY data'!$E$2:$E$49915=$A14)*('HR1 - PY data'!$F$2:$F49915))} -> 0 | E14: {=SUMPRODUCT(('HR1 - PY data'!$A$2:$A$49915=$C$4)*('HR1 - PY data'!$B$2:$B$49915=$D$4)*('HR1 - PY data'!$C$2:$C$49915=$E$4)*('HR1 - PY data'!$D$2:$D$49915=E$11)*('HR1 - PY data'!$E$2:$E$49915=$A14)*('HR1 - PY data'!$F$2:$F49915))} -> 0 | F14: {=SUMPRODUCT(('HR1 - PY data'!$A$2:$A$49915=$C$4)*('HR1 - PY data'!$B$2:$B$49915=$D$4)*('HR1 - PY data'!$C$2:$C$49915=$E$4)*('HR1 - PY data'!$D$2:$D$49915=F$11)*('HR1 - PY data'!$E$2:$E$49915=$A14)*('HR1 - PY data'!$F$2:$F49915))} -> 0
A15: Station Manager | B15: {=SUMPRODUCT(('HR1 - PY data'!$A$2:$A$49915=$C$4)*('HR1 - PY data'!$B$2:$B$49915=$D$4)*('HR1 - PY data'!$C$2:$C$49915=$E$4)*('HR1 - PY data'!$D$2:$D$49915=B$11)*('HR1 - PY data'!$E$2:$E$49915=$A15)*('HR1 - PY data'!$F$2:$F49915))} -> 0 | C15: {=SUMPRODUCT(('HR1 - PY data'!$A$2:$A$49915=$C$4)*('HR1 - PY data'!$B$2:$B$49915=$D$4)*('HR1 - PY data'!$C$2:$C$49915=$E$4)*('HR1 - PY data'!$D$2:$D$49915=C$11)*('HR1 - PY data'!$E$2:$E$49915=$A15)*('HR1 - PY data'!$F$2:$F49915))} -> 0 | D15: {=SUMPRODUCT(('HR1 - PY data'!$A$2:$A$49915=$C$4)*('HR1 - PY data'!$B$2:$B$49915=$D$4)*('HR1 - PY data'!$C$2:$C$49915=$E$4)*('HR1 - PY data'!$D$2:$D$49915=D$11)*('HR1 - PY data'!$E$2:$E$49915=$A15)*('HR1 - PY data'!$F$2:$F49915))} -> 0 | E15: {=SUMPRODUCT(('HR1 - PY data'!$A$2:$A$49915=$C$4)*('HR1 - PY data'!$B$2:$B$49915=$D$4)*('HR1 - PY data'!$C$2:$C$49915=$E$4)*('HR1 - PY data'!$D$2:$D$49915=E$11)*('HR1 - PY data'!$E$2:$E$49915=$A15)*('HR1 - PY data'!$F$2:$F49915))} -> 0 | F15: {=SUMPRODUCT(('HR1 - PY data'!$A$2:$A$49915=$C$4)*('HR1 - PY data'!$B$2:$B$49915=$D$4)*('HR1 - PY data'!$C$2:$C$49915=$E$4)*('HR1 - PY data'!$D$2:$D$49915=F$11)*('HR1 - PY data'!$E$2:$E$49915=$A15)*('HR1 - PY data'!$F$2:$F49915))} -> 0
A16: Watch Manager | B16: {=SUMPRODUCT(('HR1 - PY data'!$A$2:$A$49915=$C$4)*('HR1 - PY data'!$B$2:$B$49915=$D$4)*('HR1 - PY data'!$C$2:$C$49915=$E$4)*('HR1 - PY data'!$D$2:$D$49915=B$11)*('HR1 - PY data'!$E$2:$E$49915=$A16)*('HR1 - PY data'!$F$2:$F49915))} -> 0 | C16: {=SUMPRODUCT(('HR1 - PY data'!$A$2:$A$49915=$C$4)*('HR1 - PY data'!$B$2:$B$49915=$D$4)*('HR1 - PY data'!$C$2:$C$49915=$E$4)*('HR1 - PY data'!$D$2:$D$49915=C$11)*('HR1 - PY data'!$E$2:$E$49915=$A16)*('HR1 - PY data'!$F$2:$F49915))} -> 0 | D16: {=SUMPRODUCT(('HR1 - PY data'!$A$2:$A$49915=$C$4)*('HR1 - PY data'!$B$2:$B$49915=$D$4)*('HR1 - PY data'!$C$2:$C$49915=$E$4)*('HR1 - PY data'!$D$2:$D$49915=D$11)*('HR1 - PY data'!$E$2:$E$49915=$A16)*('HR1 - PY data'!$F$2:$F49915))} -> 0 | E16: {=SUMPRODUCT(('HR1 - PY data'!$A$2:$A$49915=$C$4)*('HR1 - PY data'!$B$2:$B$49915=$D$4)*('HR1 - PY data'!$C$2:$C$49915=$E$4)*('HR1 - PY data'!$D$2:$D$49915=E$11)*('HR1 - PY data'!$E$2:$E$49915=$A16)*('HR1 - PY data'!$F$2:$F49915))} -> 0 | F16: {=SUMPRODUCT(('HR1 - PY data'!$A$2:$A$49915=$C$4)*('HR1 - PY data'!$B$2:$B$49915=$D$4)*('HR1 - PY data'!$C$2:$C$49915=$E$4)*('HR1 - PY data'!$D$2:$D$49915=F$11)*('HR1 - PY data'!$E$2:$E$49915=$A16)*('HR1 - PY data'!$F$2:$F49915))} -> 0
A17: Crew Manager | B17: {=SUMPRODUCT(('HR1 - PY data'!$A$2:$A$49915=$C$4)*('HR1 - PY data'!$B$2:$B$49915=$D$4)*('HR1 - PY data'!$C$2:$C$49915=$E$4)*('HR1 - PY data'!$D$2:$D$49915=B$11)*('HR1 - PY data'!$E$2:$E$49915=$A17)*('HR1 - PY data'!$F$2:$F49915))} -> 0 | C17: {=SUMPRODUCT(('HR1 - PY data'!$A$2:$A$49915=$C$4)*('HR1 - PY data'!$B$2:$B$49915=$D$4)*('HR1 - PY data'!$C$2:$C$49915=$E$4)*('HR1 - PY data'!$D$2:$D$49915=C$11)*('HR1 - PY data'!$E$2:$E$49915=$A17)*('HR1 - PY data'!$F$2:$F49915))} -> 0 | D17: {=SUMPRODUCT(('HR1 - PY data'!$A$2:$A$49915=$C$4)*('HR1 - PY data'!$B$2:$B$49915=$D$4)*('HR1 - PY data'!$C$2:$C$49915=$E$4)*('HR1 - PY data'!$D$2:$D$49915=D$11)*('HR1 - PY data'!$E$2:$E$49915=$A17)*('HR1 - PY data'!$F$2:$F49915))} -> 0 | E17: {=SUMPRODUCT(('HR1 - PY data'!$A$2:$A$49915=$C$4)*('HR1 - PY data'!$B$2:$B$49915=$D$4)*('HR1 - PY data'!$C$2:$C$49915=$E$4)*('HR1 - PY data'!$D$2:$D$49915=E$11)*('HR1 - PY data'!$E$2:$E$49915=$A17)*('HR1 - PY data'!$F$2:$F49915))} -> 0 | F17: {=SUMPRODUCT(('HR1 - PY data'!$A$2:$A$49915=$C$4)*('HR1 - PY data'!$B$2:$B$49915=$D$4)*('HR1 - PY data'!$C$2:$C$49915=$E$4)*('HR1 - PY data'!$D$2:$D$49915=F$11)*('HR1 - PY data'!$E$2:$E$49915=$A17)*('HR1 - PY data'!$F$2:$F49915))} -> 0
A18: Firefighter | B18: {=SUMPRODUCT(('HR1 - PY data'!$A$2:$A$49915=$C$4)*('HR1 - PY data'!$B$2:$B$49915=$D$4)*('HR1 - PY data'!$C$2:$C$49915=$E$4)*('HR1 - PY data'!$D$2:$D$49915=B$11)*('HR1 - PY data'!$E$2:$E$49915=$A18)*('HR1 - PY data'!$F$2:$F49915))} -> 0 | C18: {=SUMPRODUCT(('HR1 - PY data'!$A$2:$A$49915=$C$4)*('HR1 - PY data'!$B$2:$B$49915=$D$4)*('HR1 - PY data'!$C$2:$C$49915=$E$4)*('HR1 - PY data'!$D$2:$D$49915=C$11)*('HR1 - PY data'!$E$2:$E$49915=$A18)*('HR1 - PY data'!$F$2:$F49915))} -> 0 | D18: {=SUMPRODUCT(('HR1 - PY data'!$A$2:$A$49915=$C$4)*('HR1 - PY data'!$B$2:$B$49915=$D$4)*('HR1 - PY data'!$C$2:$C$49915=$E$4)*('HR1 - PY data'!$D$2:$D$49915=D$11)*('HR1 - PY data'!$E$2:$E$49915=$A18)*('HR1 - PY data'!$F$2:$F49915))} -> 0 | E18: {=SUMPRODUCT(('HR1 - PY data'!$A$2:$A$49915=$C$4)*('HR1 - PY data'!$B$2:$B$49915=$D$4)*('HR1 - PY data'!$C$2:$C$49915=$E$4)*('HR1 - PY data'!$D$2:$D$49915=E$11)*('HR1 - PY data'!$E$2:$E$49915=$A18)*('HR1 - PY data'!$F$2:$F49915))} -> 0 | F18: {=SUMPRODUCT(('HR1 - PY data'!$A$2:$A$49915=$C$4)*('HR1 - PY data'!$B$2:$B$49915=$D$4)*('HR1 - PY data'!$C$2:$C$49915=$E$4)*('HR1 - PY data'!$D$2:$D$49915=F$11)*('HR1 - PY data'!$E$2:$E$49915=$A18)*('HR1 - PY data'!$F$2:$F49915))} -> 0
A19: Total | B19: =SUM(B12:B18) -> 0 | C19: =SUM(C12:C18) -> 0 | D19: =SUM(D12:D18) -> 0 | E19: =SUM(E12:E18) -> 0 | F19: =SUM(F12:F18) -> 0
B25: Support staff
A26: Total | B26: {=SUMPRODUCT(('HR1 - PY data'!$A$2:$A$49915=$C$4)*('HR1 - PY data'!$B$2:$B$49915=$D$4)*('HR1 - PY data'!$C$2:$C$49915=$E$4)*('HR1 - PY data'!$D$2:$D$49915=B$25)*('HR1 - PY data'!$E$2:$E$49915=$A26)*('HR1 - PY data'!$F$2:$F49915))} -> 0

Sheet HR1
A6: HR1 - Staff strength by role and contract type
A8: By role and contract type at 31st March 2026: | H8: QA checks versus data submitted last year
B9: Wholetime Firefighters (FTE) | C9: On call firefighters (FTE, in 24 hour units of cover) | F9: Fire Control Staff (FTE) | H9: Cells highlighted yellow following data entry indicate a significant change between the figures inputted this year relative to the previous year. Please double check the relevant figures prior to submitting this return and provide explanatory commentary below if necessary.
C11: All on call staff | D11: Of which also wholetime but on separate contract | E11: Of which part of wholetime contract
A12: Brigade Manager
A13: Area Manager
A14: Group Manager
A15: Station Manager
A16: Watch Manager
A17: Crew Manager
A18: Firefighter
A19: Total | B19: =SUM(B12:B18) -> 0 | C19: =SUM(C12:C18) -> 0 | D19: =SUM(D14:D18) -> 0 | E19: =SUM(E14:E18) -> 0 | F19: =SUM(F12:F18) -> 0
A24: Support staff at 31st March 2026:
B25: Support Staff (FTE)
A26: Total

Sheet HR2to5 - PY data
A1: SHEET | B1: CALENDAR_YEAR | C1: FRS_NAME | D1: ROLE | E1: RANK | F1: DIVERSITY_CHARACTERISTIC | G1: TOTAL

Sheet HR2 PY
C4: HR2 | D4: =VLOOKUP(Cover!A6,Cover!B319:D335,2,FALSE) -> 2025 | E4: =Cover!A10 -> North West Fire Control
B10: Men_17to24 | C10: Women_17to24 | D10: Other_17to24 | E10: Unknown_17to24 | F10: Total | G10: Men_25to35 | H10: Women_25to35 | I10: Other_25to35 | J10: Unknown_25to35 | K10: Total | L10: Men_36to45 | M10: Women_36to45 | N10: Other_36to45 | O10: Unknown_36to45 | P10: Total | Q10: Men_46to55 | R10: Women_46to55 | S10: Other_46to55 | T10: Unknown_46to55 | U10: Total
A11: Brigade Manager | B11: {=SUMPRODUCT(('HR2to5 - PY data'!$A$2:$A$48992=$C$4)*('HR2to5 - PY data'!$B$2:$B$48992=$D$4)*('HR2to5 - PY data'!$C$2:$C$48992=$E$4)*('HR2to5 - PY data'!$F$2:$F$48992=B$10)*('HR2to5 - PY data'!$E$2:$E$48992=$A11)*('HR2to5 - PY data'!$G$2:$G$48992))} -> 0 | C11: {=SUMPRODUCT(('HR2to5 - PY data'!$A$2:$A$48992=$C$4)*('HR2to5 - PY data'!$B$2:$B$48992=$D$4)*('HR2to5 - PY data'!$C$2:$C$48992=$E$4)*('HR2to5 - PY data'!$F$2:$F$48992=C$10)*('HR2to5 - PY data'!$E$2:$E$48992=$A11)*('HR2to5 - PY data'!$G$2:$G$48992))} -> 0 | D11: {=SUMPRODUCT(('HR2to5 - PY data'!$A$2:$A$48992=$C$4)*('HR2to5 - PY data'!$B$2:$B$48992=$D$4)*('HR2to5 - PY data'!$C$2:$C$48992=$E$4)*('HR2to5 - PY data'!$F$2:$F$48992=D$10)*('HR2to5 - PY data'!$E$2:$E$48992=$A11)*('HR2to5 - PY data'!$G$2:$G$48992))} -> 0 | E11: {=SUMPRODUCT(('HR2to5 - PY data'!$A$2:$A$48992=$C$4)*('HR2to5 - PY data'!$B$2:$B$48992=$D$4)*('HR2to5 - PY data'!$C$2:$C$48992=$E$4)*('HR2to5 - PY data'!$F$2:$F$48992=E$10)*('HR2to5 - PY data'!$E$2:$E$48992=$A11)*('HR2to5 - PY data'!$G$2:$G$48992))} -> 0 | F11: =SUM(B11:E11) -> 0 | G11: {=SUMPRODUCT(('HR2to5 - PY data'!$A$2:$A$48992=$C$4)*('HR2to5 - PY data'!$B$2:$B$48992=$D$4)*('HR2to5 - PY data'!$C$2:$C$48992=$E$4)*('HR2to5 - PY data'!$F$2:$F$48992=G$10)*('HR2to5 - PY data'!$E$2:$E$48992=$A11)*('HR2to5 - PY data'!$G$2:$G$48992))} -> 0 | H11: {=SUMPRODUCT(('HR2to5 - PY data'!$A$2:$A$48992=$C$4)*('HR2to5 - PY data'!$B$2:$B$48992=$D$4)*('HR2to5 - PY data'!$C$2:$C$48992=$E$4)*('HR2to5 - PY data'!$F$2:$F$48992=H$10)*('HR2to5 - PY data'!$E$2:$E$48992=$A11)*('HR2to5 - PY data'!$G$2:$G$48992))} -> 0 | I11: {=SUMPRODUCT(('HR2to5 - PY data'!$A$2:$A$48992=$C$4)*('HR2to5 - PY data'!$B$2:$B$48992=$D$4)*('HR2to5 - PY data'!$C$2:$C$48992=$E$4)*('HR2to5 - PY data'!$F$2:$F$48992=I$10)*('HR2to5 - PY data'!$E$2:$E$48992=$A11)*('HR2to5 - PY data'!$G$2:$G$48992))} -> 0 | J11: {=SUMPRODUCT(('HR2to5 - PY data'!$A$2:$A$48992=$C$4)*('HR2to5 - PY data'!$B$2:$B$48992=$D$4)*('HR2to5 - PY data'!$C$2:$C$48992=$E$4)*('HR2to5 - PY data'!$F$2:$F$48992=J$10)*('HR2to5 - PY data'!$E$2:$E$48992=$A11)*('HR2to5 - PY data'!$G$2:$G$48992))} -> 0 | K11: =SUM(G11:J11) -> 0 | L11: {=SUMPRODUCT(('HR2to5 - PY data'!$A$2:$A$48992=$C$4)*('HR2to5 - PY data'!$B$2:$B$48992=$D$4)*('HR2to5 - PY data'!$C$2:$C$48992=$E$4)*('HR2to5 - PY data'!$F$2:$F$48992=L$10)*('HR2to5 - PY data'!$E$2:$E$48992=$A11)*('HR2to5 - PY data'!$G$2:$G$48992))} -> 0 | M11: {=SUMPRODUCT(('HR2to5 - PY data'!$A$2:$A$48992=$C$4)*('HR2to5 - PY data'!$B$2:$B$48992=$D$4)*('HR2to5 - PY data'!$C$2:$C$48992=$E$4)*('HR2to5 - PY data'!$F$2:$F$48992=M$10)*('HR2to5 - PY data'!$E$2:$E$48992=$A11)*('HR2to5 - PY data'!$G$2:$G$48992))} -> 0 | N11: {=SUMPRODUCT(('HR2to5 - PY data'!$A$2:$A$48992=$C$4)*('HR2to5 - PY data'!$B$2:$B$48992=$D$4)*('HR2to5 - PY data'!$C$2:$C$48992=$E$4)*('HR2to5 - PY data'!$F$2:$F$48992=N$10)*('HR2to5 - PY data'!$E$2:$E$48992=$A11)*('HR2to5 - PY data'!$G$2:$G$48992))} -> 0 | O11: {=SUMPRODUCT(('HR2to5 - PY data'!$A$2:$A$48992=$C$4)*('HR2to5 - PY data'!$B$2:$B$48992=$D$4)*('HR2to5 - PY data'!$C$2:$C$48992=$E$4)*('HR2to5 - PY data'!$F$2:$F$48992=O$10)*('HR2to5 - PY data'!$E$2:$E$48992=$A11)*('HR2to5 - PY data'!$G$2:$G$48992))} -> 0 | P11: =SUM(L11:O11) -> 0 | Q11: {=SUMPRODUCT(('HR2to5 - PY data'!$A$2:$A$48992=$C$4)*('HR2to5 - PY data'!$B$2:$B$48992=$D$4)*('HR2to5 - PY data'!$C$2:$C$48992=$E$4)*('HR2to5 - PY data'!$F$2:$F$48992=Q$10)*('HR2to5 - PY data'!$E$2:$E$48992=$A11)*('HR2to5 - PY data'!$G$2:$G$48992))} -> 0 | R11: {=SUMPRODUCT(('HR2to5 - PY data'!$A$2:$A$48992=$C$4)*('HR2to5 - PY data'!$B$2:$B$48992=$D$4)*('HR2to5 - PY data'!$C$2:$C$48992=$E$4)*('HR2to5 - PY data'!$F$2:$F$48992=R$10)*('HR2to5 - PY data'!$E$2:$E$48992=$A11)*('HR2to5 - PY data'!$G$2:$G$48992))} -> 0 | S11: {=SUMPRODUCT(('HR2to5 - PY data'!$A$2:$A$48992=$C$4)*('HR2to5 - PY data'!$B$2:$B$48992=$D$4)*('HR2to5 - PY data'!$C$2:$C$48992=$E$4)*('HR2to5 - PY data'!$F$2:$F$48992=S$10)*('HR2to5 - PY data'!$E$2:$E$48992=$A11)*('HR2to5 - PY data'!$G$2:$G$48992))} -> 0 | T11: {=SUMPRODUCT(('HR2to5 - PY data'!$A$2:$A$48992=$C$4)*('HR2to5 - PY data'!$B$2:$B$48992=$D$4)*('HR2to5 - PY data'!$C$2:$C$48992=$E$4)*('HR2to5 - PY data'!$F$2:$F$48992=T$10)*('HR2to5 - PY data'!$E$2:$E$48992=$A11)*('HR2to5 - PY data'!$G$2:$G$48992))} -> 0 | U11: =SUM(Q11:T11) -> 0
A12: Area Manager | B12: {=SUMPRODUCT(('HR2to5 - PY data'!$A$2:$A$48992=$C$4)*('HR2to5 - PY data'!$B$2:$B$48992=$D$4)*('HR2to5 - PY data'!$C$2:$C$48992=$E$4)*('HR2to5 - PY data'!$F$2:$F$48992=B$10)*('HR2to5 - PY data'!$E$2:$E$48992=$A12)*('HR2to5 - PY data'!$G$2:$G$48992))} -> 0 | C12: {=SUMPRODUCT(('HR2to5 - PY data'!$A$2:$A$48992=$C$4)*('HR2to5 - PY data'!$B$2:$B$48992=$D$4)*('HR2to5 - PY data'!$C$2:$C$48992=$E$4)*('HR2to5 - PY data'!$F$2:$F$48992=C$10)*('HR2to5 - PY data'!$E$2:$E$48992=$A12)*('HR2to5 - PY data'!$G$2:$G$48992))} -> 0 | D12: {=SUMPRODUCT(('HR2to5 - PY data'!$A$2:$A$48992=$C$4)*('HR2to5 - PY data'!$B$2:$B$48992=$D$4)*('HR2to5 - PY data'!$C$2:$C$48992=$E$4)*('HR2to5 - PY data'!$F$2:$F$48992=D$10)*('HR2to5 - PY data'!$E$2:$E$48992=$A12)*('HR2to5 - PY data'!$G$2:$G$48992))} -> 0 | E12: {=SUMPRODUCT(('HR2to5 - PY data'!$A$2:$A$48992=$C$4)*('HR2to5 - PY data'!$B$2:$B$48992=$D$4)*('HR2to5 - PY data'!$C$2:$C$48992=$E$4)*('HR2to5 - PY data'!$F$2:$F$48992=E$10)*('HR2to5 - PY data'!$E$2:$E$48992=$A12)*('HR2to5 - PY data'!$G$2:$G$48992))} -> 0 | F12: =SUM(B12:E12) -> 0 | G12: {=SUMPRODUCT(('HR2to5 - PY data'!$A$2:$A$48992=$C$4)*('HR2to5 - PY data'!$B$2:$B$48992=$D$4)*('HR2to5 - PY data'!$C$2:$C$48992=$E$4)*('HR2to5 - PY data'!$F$2:$F$48992=G$10)*('HR2to5 - PY data'!$E$2:$E$48992=$A12)*('HR2to5 - PY data'!$G$2:$G$48992))} -> 0 | H12: {=SUMPRODUCT(('HR2to5 - PY data'!$A$2:$A$48992=$C$4)*('HR2to5 - PY data'!$B$2:$B$48992=$D$4)*('HR2to5 - PY data'!$C$2:$C$48992=$E$4)*('HR2to5 - PY data'!$F$2:$F$48992=H$10)*('HR2to5 - PY data'!$E$2:$E$48992=$A12)*('HR2to5 - PY data'!$G$2:$G$48992))} -> 0 | I12: {=SUMPRODUCT(('HR2to5 - PY data'!$A$2:$A$48992=$C$4)*('HR2to5 - PY data'!$B$2:$B$48992=$D$4)*('HR2to5 - PY data'!$C$2:$C$48992=$E$4)*('HR2to5 - PY data'!$F$2:$F$48992=I$10)*('HR2to5 - PY data'!$E$2:$E$48992=$A12)*('HR2to5 - PY data'!$G$2:$G$48992))} -> 0 | J12: {=SUMPRODUCT(('HR2to5 - PY data'!$A$2:$A$48992=$C$4)*('HR2to5 - PY data'!$B$2:$B$48992=$D$4)*('HR2to5 - PY data'!$C$2:$C$48992=$E$4)*('HR2to5 - PY data'!$F$2:$F$48992=J$10)*('HR2to5 - PY data'!$E$2:$E$48992=$A12)*('HR2to5 - PY data'!$G$2:$G$48992))} -> 0 | K12: =SUM(G12:J12) -> 0 | L12: {=SUMPRODUCT(('HR2to5 - PY data'!$A$2:$A$48992=$C$4)*('HR2to5 - PY data'!$B$2:$B$48992=$D$4)*('HR2to5 - PY data'!$C$2:$C$48992=$E$4)*('HR2to5 - PY data'!$F$2:$F$48992=L$10)*('HR2to5 - PY data'!$E$2:$E$48992=$A12)*('HR2to5 - PY data'!$G$2:$G$48992))} -> 0 | M12: {=SUMPRODUCT(('HR2to5 - PY data'!$A$2:$A$48992=$C$4)*('HR2to5 - PY data'!$B$2:$B$48992=$D$4)*('HR2to5 - PY data'!$C$2:$C$48992=$E$4)*('HR2to5 - PY data'!$F$2:$F$48992=M$10)*('HR2to5 - PY data'!$E$2:$E$48992=$A12)*('HR2to5 - PY data'!$G$2:$G$48992))} -> 0 | N12: {=SUMPRODUCT(('HR2to5 - PY data'!$A$2:$A$48992=$C$4)*('HR2to5 - PY data'!$B$2:$B$48992=$D$4)*('HR2to5 - PY data'!$C$2:$C$48992=$E$4)*('HR2to5 - PY data'!$F$2:$F$48992=N$10)*('HR2to5 - PY data'!$E$2:$E$48992=$A12)*('HR2to5 - PY data'!$G$2:$G$48992))} -> 0 | O12: {=SUMPRODUCT(('HR2to5 - PY data'!$A$2:$A$48992=$C$4)*('HR2to5 - PY data'!$B$2:$B$48992=$D$4)*('HR2to5 - PY data'!$C$2:$C$48992=$E$4)*('HR2to5 - PY data'!$F$2:$F$48992=O$10)*('HR2to5 - PY data'!$E$2:$E$48992=$A12)*('HR2to5 - PY data'!$G$2:$G$48992))} -> 0 | P12: =SUM(L12:O12) -> 0 | Q12: {=SUMPRODUCT(('HR2to5 - PY data'!$A$2:$A$48992=$C$4)*('HR2to5 - PY data'!$B$2:$B$48992=$D$4)*('HR2to5 - PY data'!$C$2:$C$48992=$E$4)*('HR2to5 - PY data'!$F$2:$F$48992=Q$10)*('HR2to5 - PY data'!$E$2:$E$48992=$A12)*('HR2to5 - PY data'!$G$2:$G$48992))} -> 0 | R12: {=SUMPRODUCT(('HR2to5 - PY data'!$A$2:$A$48992=$C$4)*('HR2to5 - PY data'!$B$2:$B$48992=$D$4)*('HR2to5 - PY data'!$C$2:$C$48992=$E$4)*('HR2to5 - PY data'!$F$2:$F$48992=R$10)*('HR2to5 - PY data'!$E$2:$E$48992=$A12)*('HR2to5 - PY data'!$G$2:$G$48992))} -> 0 | S12: {=SUMPRODUCT(('HR2to5 - PY data'!$A$2:$A$48992=$C$4)*('HR2to5 - PY data'!$B$2:$B$48992=$D$4)*('HR2to5 - PY data'!$C$2:$C$48992=$E$4)*('HR2to5 - PY data'!$F$2:$F$48992=S$10)*('HR2to5 - PY data'!$E$2:$E$48992=$A12)*('HR2to5 - PY data'!$G$2:$G$48992))} -> 0 | T12: {=SUMPRODUCT(('HR2to5 - PY data'!$A$2:$A$48992=$C$4)*('HR2to5 - PY data'!$B$2:$B$48992=$D$4)*('HR2to5 - PY data'!$C$2:$C$48992=$E$4)*('HR2to5 - PY data'!$F$2:$F$48992=T$10)*('HR2to5 - PY data'!$E$2:$E$48992=$A12)*('HR2to5 - PY data'!$G$2:$G$48992))} -> 0 | U12: =SUM(Q12:T12) -> 0
A13: Group Manager | B13: {=SUMPRODUCT(('HR2to5 - PY data'!$A$2:$A$48992=$C$4)*('HR2to5 - PY data'!$B$2:$B$48992=$D$4)*('HR2to5 - PY data'!$C$2:$C$48992=$E$4)*('HR2to5 - PY data'!$F$2:$F$48992=B$10)*('HR2to5 - PY data'!$E$2:$E$48992=$A13)*('HR2to5 - PY data'!$G$2:$G$48992))} -> 0 | C13: {=SUMPRODUCT(('HR2to5 - PY data'!$A$2:$A$48992=$C$4)*('HR2to5 - PY data'!$B$2:$B$48992=$D$4)*('HR2to5 - PY data'!$C$2:$C$48992=$E$4)*('HR2to5 - PY data'!$F$2:$F$48992=C$10)*('HR2to5 - PY data'!$E$2:$E$48992=$A13)*('HR2to5 - PY data'!$G$2:$G$48992))} -> 0 | D13: {=SUMPRODUCT(('HR2to5 - PY data'!$A$2:$A$48992=$C$4)*('HR2to5 - PY data'!$B$2:$B$48992=$D$4)*('HR2to5 - PY data'!$C$2:$C$48992=$E$4)*('HR2to5 - PY data'!$F$2:$F$48992=D$10)*('HR2to5 - PY data'!$E$2:$E$48992=$A13)*('HR2to5 - PY data'!$G$2:$G$48992))} -> 0 | E13: {=SUMPRODUCT(('HR2to5 - PY data'!$A$2:$A$48992=$C$4)*('HR2to5 - PY data'!$B$2:$B$48992=$D$4)*('HR2to5 - PY data'!$C$2:$C$48992=$E$4)*('HR2to5 - PY data'!$F$2:$F$48992=E$10)*('HR2to5 - PY data'!$E$2:$E$48992=$A13)*('HR2to5 - PY data'!$G$2:$G$48992))} -> 0 | F13: =SUM(B13:E13) -> 0 | G13: {=SUMPRODUCT(('HR2to5 - PY data'!$A$2:$A$48992=$C$4)*('HR2to5 - PY data'!$B$2:$B$48992=$D$4)*('HR2to5 - PY data'!$C$2:$C$48992=$E$4)*('HR2to5 - PY data'!$F$2:$F$48992=G$10)*('HR2to5 - PY data'!$E$2:$E$48992=$A13)*('HR2to5 - PY data'!$G$2:$G$48992))} -> 0 | H13: {=SUMPRODUCT(('HR2to5 - PY data'!$A$2:$A$48992=$C$4)*('HR2to5 - PY data'!$B$2:$B$48992=$D$4)*('HR2to5 - PY data'!$C$2:$C$48992=$E$4)*('HR2to5 - PY data'!$F$2:$F$48992=H$10)*('HR2to5 - PY data'!$E$2:$E$48992=$A13)*('HR2to5 - PY data'!$G$2:$G$48992))} -> 0 | I13: {=SUMPRODUCT(('HR2to5 - PY data'!$A$2:$A$48992=$C$4)*('HR2to5 - PY data'!$B$2:$B$48992=$D$4)*('HR2to5 - PY data'!$C$2:$C$48992=$E$4)*('HR2to5 - PY data'!$F$2:$F$48992=I$10)*('HR2to5 - PY data'!$E$2:$E$48992=$A13)*('HR2to5 - PY data'!$G$2:$G$48992))} -> 0 | J13: {=SUMPRODUCT(('HR2to5 - PY data'!$A$2:$A$48992=$C$4)*('HR2to5 - PY data'!$B$2:$B$48992=$D$4)*('HR2to5 - PY data'!$C$2:$C$48992=$E$4)*('HR2to5 - PY data'!$F$2:$F$48992=J$10)*('HR2to5 - PY data'!$E$2:$E$48992=$A13)*('HR2to5 - PY data'!$G$2:$G$48992))} -> 0 | K13: =SUM(G13:J13) -> 0 | L13: {=SUMPRODUCT(('HR2to5 - PY data'!$A$2:$A$48992=$C$4)*('HR2to5 - PY data'!$B$2:$B$48992=$D$4)*('HR2to5 - PY data'!$C$2:$C$48992=$E$4)*('HR2to5 - PY data'!$F$2:$F$48992=L$10)*('HR2to5 - PY data'!$E$2:$E$48992=$A13)*('HR2to5 - PY data'!$G$2:$G$48992))} -> 0 | M13: {=SUMPRODUCT(('HR2to5 - PY data'!$A$2:$A$48992=$C$4)*('HR2to5 - PY data'!$B$2:$B$48992=$D$4)*('HR2to5 - PY data'!$C$2:$C$48992=$E$4)*('HR2to5 - PY data'!$F$2:$F$48992=M$10)*('HR2to5 - PY data'!$E$2:$E$48992=$A13)*('HR2to5 - PY data'!$G$2:$G$48992))} -> 0 | N13: {=SUMPRODUCT(('HR2to5 - PY data'!$A$2:$A$48992=$C$4)*('HR2to5 - PY data'!$B$2:$B$48992=$D$4)*('HR2to5 - PY data'!$C$2:$C$48992=$E$4)*('HR2to5 - PY data'!$F$2:$F$48992=N$10)*('HR2to5 - PY data'!$E$2:$E$48992=$A13)*('HR2to5 - PY data'!$G$2:$G$48992))} -> 0 | O13: {=SUMPRODUCT(('HR2to5 - PY data'!$A$2:$A$48992=$C$4)*('HR2to5 - PY data'!$B$2:$B$48992=$D$4)*('HR2to5 - PY data'!$C$2:$C$48992=$E$4)*('HR2to5 - PY data'!$F$2:$F$48992=O$10)*('HR2to5 - PY data'!$E$2:$E$48992=$A13)*('HR2to5 - PY data'!$G$2:$G$48992))} -> 0 | P13: =SUM(L13:O13) -> 0 | Q13: {=SUMPRODUCT(('HR2to5 - PY data'!$A$2:$A$48992=$C$4)*('HR2to5 - PY data'!$B$2:$B$48992=$D$4)*('HR2to5 - PY data'!$C$2:$C$48992=$E$4)*('HR2to5 - PY data'!$F$2:$F$48992=Q$10)*('HR2to5 - PY data'!$E$2:$E$48992=$A13)*('HR2to5 - PY data'!$G$2:$G$48992))} -> 0 | R13: {=SUMPRODUCT(('HR2to5 - PY data'!$A$2:$A$48992=$C$4)*('HR2to5 - PY data'!$B$2:$B$48992=$D$4)*('HR2to5 - PY data'!$C$2:$C$48992=$E$4)*('HR2to5 - PY data'!$F$2:$F$48992=R$10)*('HR2to5 - PY data'!$E$2:$E$48992=$A13)*('HR2to5 - PY data'!$G$2:$G$48992))} -> 0 | S13: {=SUMPRODUCT(('HR2to5 - PY data'!$A$2:$A$48992=$C$4)*('HR2to5 - PY data'!$B$2:$B$48992=$D$4)*('HR2to5 - PY data'!$C$2:$C$48992=$E$4)*('HR2to5 - PY data'!$F$2:$F$48992=S$10)*('HR2to5 - PY data'!$E$2:$E$48992=$A13)*('HR2to5 - PY data'!$G$2:$G$48992))} -> 0 | T13: {=SUMPRODUCT(('HR2to5 - PY data'!$A$2:$A$48992=$C$4)*('HR2to5 - PY data'!$B$2:$B$48992=$D$4)*('HR2to5 - PY data'!$C$2:$C$48992=$E$4)*('HR2to5 - PY data'!$F$2:$F$48992=T$10)*('HR2to5 - PY data'!$E$2:$E$48992=$A13)*('HR2to5 - PY data'!$G$2:$G$48992))} -> 0 | U13: =SUM(Q13:T13) -> 0
A14: Station Manager | B14: {=SUMPRODUCT(('HR2to5 - PY data'!$A$2:$A$48992=$C$4)*('HR2to5 - PY data'!$B$2:$B$48992=$D$4)*('HR2to5 - PY data'!$C$2:$C$48992=$E$4)*('HR2to5 - PY data'!$F$2:$F$48992=B$10)*('HR2to5 - PY data'!$E$2:$E$48992=$A14)*('HR2to5 - PY data'!$G$2:$G$48992))} -> 0 | C14: {=SUMPRODUCT(('HR2to5 - PY data'!$A$2:$A$48992=$C$4)*('HR2to5 - PY data'!$B$2:$B$48992=$D$4)*('HR2to5 - PY data'!$C$2:$C$48992=$E$4)*('HR2to5 - PY data'!$F$2:$F$48992=C$10)*('HR2to5 - PY data'!$E$2:$E$48992=$A14)*('HR2to5 - PY data'!$G$2:$G$48992))} -> 0 | D14: {=SUMPRODUCT(('HR2to5 - PY data'!$A$2:$A$48992=$C$4)*('HR2to5 - PY data'!$B$2:$B$48992=$D$4)*('HR2to5 - PY data'!$C$2:$C$48992=$E$4)*('HR2to5 - PY data'!$F$2:$F$48992=D$10)*('HR2to5 - PY data'!$E$2:$E$48992=$A14)*('HR2to5 - PY data'!$G$2:$G$48992))} -> 0 | E14: {=SUMPRODUCT(('HR2to5 - PY data'!$A$2:$A$48992=$C$4)*('HR2to5 - PY data'!$B$2:$B$48992=$D$4)*('HR2to5 - PY data'!$C$2:$C$48992=$E$4)*('HR2to5 - PY data'!$F$2:$F$48992=E$10)*('HR2to5 - PY data'!$E$2:$E$48992=$A14)*('HR2to5 - PY data'!$G$2:$G$48992))} -> 0 | F14: =SUM(B14:E14) -> 0 | G14: {=SUMPRODUCT(('HR2to5 - PY data'!$A$2:$A$48992=$C$4)*('HR2to5 - PY data'!$B$2:$B$48992=$D$4)*('HR2to5 - PY data'!$C$2:$C$48992=$E$4)*('HR2to5 - PY data'!$F$2:$F$48992=G$10)*('HR2to5 - PY data'!$E$2:$E$48992=$A14)*('HR2to5 - PY data'!$G$2:$G$48992))} -> 0 | H14: {=SUMPRODUCT(('HR2to5 - PY data'!$A$2:$A$48992=$C$4)*('HR2to5 - PY data'!$B$2:$B$48992=$D$4)*('HR2to5 - PY data'!$C$2:$C$48992=$E$4)*('HR2to5 - PY data'!$F$2:$F$48992=H$10)*('HR2to5 - PY data'!$E$2:$E$48992=$A14)*('HR2to5 - PY data'!$G$2:$G$48992))} -> 0 | I14: {=SUMPRODUCT(('HR2to5 - PY data'!$A$2:$A$48992=$C$4)*('HR2to5 - PY data'!$B$2:$B$48992=$D$4)*('HR2to5 - PY data'!$C$2:$C$48992=$E$4)*('HR2to5 - PY data'!$F$2:$F$48992=I$10)*('HR2to5 - PY data'!$E$2:$E$48992=$A14)*('HR2to5 - PY data'!$G$2:$G$48992))} -> 0 | J14: {=SUMPRODUCT(('HR2to5 - PY data'!$A$2:$A$48992=$C$4)*('HR2to5 - PY data'!$B$2:$B$48992=$D$4)*('HR2to5 - PY data'!$C$2:$C$48992=$E$4)*('HR2to5 - PY data'!$F$2:$F$48992=J$10)*('HR2to5 - PY data'!$E$2:$E$48992=$A14)*('HR2to5 - PY data'!$G$2:$G$48992))} -> 0 | K14: =SUM(G14:J14) -> 0 | L14: {=SUMPRODUCT(('HR2to5 - PY data'!$A$2:$A$48992=$C$4)*('HR2to5 - PY data'!$B$2:$B$48992=$D$4)*('HR2to5 - PY data'!$C$2:$C$48992=$E$4)*('HR2to5 - PY data'!$F$2:$F$48992=L$10)*('HR2to5 - PY data'!$E$2:$E$48992=$A14)*('HR2to5 - PY data'!$G$2:$G$48992))} -> 0 | M14: {=SUMPRODUCT(('HR2to5 - PY data'!$A$2:$A$48992=$C$4)*('HR2to5 - PY data'!$B$2:$B$48992=$D$4)*('HR2to5 - PY data'!$C$2:$C$48992=$E$4)*('HR2to5 - PY data'!$F$2:$F$48992=M$10)*('HR2to5 - PY data'!$E$2:$E$48992=$A14)*('HR2to5 - PY data'!$G$2:$G$48992))} -> 0 | N14: {=SUMPRODUCT(('HR2to5 - PY data'!$A$2:$A$48992=$C$4)*('HR2to5 - PY data'!$B$2:$B$48992=$D$4)*('HR2to5 - PY data'!$C$2:$C$48992=$E$4)*('HR2to5 - PY data'!$F$2:$F$48992=N$10)*('HR2to5 - PY data'!$E$2:$E$48992=$A14)*('HR2to5 - PY data'!$G$2:$G$48992))} -> 0 | O14: {=SUMPRODUCT(('HR2to5 - PY data'!$A$2:$A$48992=$C$4)*('HR2to5 - PY data'!$B$2:$B$48992=$D$4)*('HR2to5 - PY data'!$C$2:$C$48992=$E$4)*('HR2to5 - PY data'!$F$2:$F$48992=O$10)*('HR2to5 - PY data'!$E$2:$E$48992=$A14)*('HR2to5 - PY data'!$G$2:$G$48992))} -> 0 | P14: =SUM(L14:O14) -> 0 | Q14: {=SUMPRODUCT(('HR2to5 - PY data'!$A$2:$A$48992=$C$4)*('HR2to5 - PY data'!$B$2:$B$48992=$D$4)*('HR2to5 - PY data'!$C$2:$C$48992=$E$4)*('HR2to5 - PY data'!$F$2:$F$48992=Q$10)*('HR2to5 - PY data'!$E$2:$E$48992=$A14)*('HR2to5 - PY data'!$G$2:$G$48992))} -> 0 | R14: {=SUMPRODUCT(('HR2to5 - PY data'!$A$2:$A$48992=$C$4)*('HR2to5 - PY data'!$B$2:$B$48992=$D$4)*('HR2to5 - PY data'!$C$2:$C$48992=$E$4)*('HR2to5 - PY data'!$F$2:$F$48992=R$10)*('HR2to5 - PY data'!$E$2:$E$48992=$A14)*('HR2to5 - PY data'!$G$2:$G$48992))} -> 0 | S14: {=SUMPRODUCT(('HR2to5 - PY data'!$A$2:$A$48992=$C$4)*('HR2to5 - PY data'!$B$2:$B$48992=$D$4)*('HR2to5 - PY data'!$C$2:$C$48992=$E$4)*('HR2to5 - PY data'!$F$2:$F$48992=S$10)*('HR2to5 - PY data'!$E$2:$E$48992=$A14)*('HR2to5 - PY data'!$G$2:$G$48992))} -> 0 | T14: {=SUMPRODUCT(('HR2to5 - PY data'!$A$2:$A$48992=$C$4)*('HR2to5 - PY data'!$B$2:$B$48992=$D$4)*('HR2to5 - PY data'!$C$2:$C$48992=$E$4)*('HR2to5 - PY data'!$F$2:$F$48992=T$10)*('HR2to5 - PY data'!$E$2:$E$48992=$A14)*('HR2to5 - PY data'!$G$2:$G$48992))} -> 0 | U14: =SUM(Q14:T14) -> 0
A15: Watch Manager | B15: {=SUMPRODUCT(('HR2to5 - PY data'!$A$2:$A$48992=$C$4)*('HR2to5 - PY data'!$B$2:$B$48992=$D$4)*('HR2to5 - PY data'!$C$2:$C$48992=$E$4)*('HR2to5 - PY data'!$F$2:$F$48992=B$10)*('HR2to5 - PY data'!$E$2:$E$48992=$A15)*('HR2to5 - PY data'!$G$2:$G$48992))} -> 0 | C15: {=SUMPRODUCT(('HR2to5 - PY data'!$A$2:$A$48992=$C$4)*('HR2to5 - PY data'!$B$2:$B$48992=$D$4)*('HR2to5 - PY data'!$C$2:$C$48992=$E$4)*('HR2to5 - PY data'!$F$2:$F$48992=C$10)*('HR2to5 - PY data'!$E$2:$E$48992=$A15)*('HR2to5 - PY data'!$G$2:$G$48992))} -> 0 | D15: {=SUMPRODUCT(('HR2to5 - PY data'!$A$2:$A$48992=$C$4)*('HR2to5 - PY data'!$B$2:$B$48992=$D$4)*('HR2to5 - PY data'!$C$2:$C$48992=$E$4)*('HR2to5 - PY data'!$F$2:$F$48992=D$10)*('HR2to5 - PY data'!$E$2:$E$48992=$A15)*('HR2to5 - PY data'!$G$2:$G$48992))} -> 0 | E15: {=SUMPRODUCT(('HR2to5 - PY data'!$A$2:$A$48992=$C$4)*('HR2to5 - PY data'!$B$2:$B$48992=$D$4)*('HR2to5 - PY data'!$C$2:$C$48992=$E$4)*('HR2to5 - PY data'!$F$2:$F$48992=E$10)*('HR2to5 - PY data'!$E$2:$E$48992=$A15)*('HR2to5 - PY data'!$G$2:$G$48992))} -> 0 | F15: =SUM(B15:E15) -> 0 | G15: {=SUMPRODUCT(('HR2to5 - PY data'!$A$2:$A$48992=$C$4)*('HR2to5 - PY data'!$B$2:$B$48992=$D$4)*('HR2to5 - PY data'!$C$2:$C$48992=$E$4)*('HR2to5 - PY data'!$F$2:$F$48992=G$10)*('HR2to5 - PY data'!$E$2:$E$48992=$A15)*('HR2to5 - PY data'!$G$2:$G$48992))} -> 0 | H15: {=SUMPRODUCT(('HR2to5 - PY data'!$A$2:$A$48992=$C$4)*('HR2to5 - PY data'!$B$2:$B$48992=$D$4)*('HR2to5 - PY data'!$C$2:$C$48992=$E$4)*('HR2to5 - PY data'!$F$2:$F$48992=H$10)*('HR2to5 - PY data'!$E$2:$E$48992=$A15)*('HR2to5 - PY data'!$G$2:$G$48992))} -> 0 | I15: {=SUMPRODUCT(('HR2to5 - PY data'!$A$2:$A$48992=$C$4)*('HR2to5 - PY data'!$B$2:$B$48992=$D$4)*('HR2to5 - PY data'!$C$2:$C$48992=$E$4)*('HR2to5 - PY data'!$F$2:$F$48992=I$10)*('HR2to5 - PY data'!$E$2:$E$48992=$A15)*('HR2to5 - PY data'!$G$2:$G$48992))} -> 0 | J15: {=SUMPRODUCT(('HR2to5 - PY data'!$A$2:$A$48992=$C$4)*('HR2to5 - PY data'!$B$2:$B$48992=$D$4)*('HR2to5 - PY data'!$C$2:$C$48992=$E$4)*('HR2to5 - PY data'!$F$2:$F$48992=J$10)*('HR2to5 - PY data'!$E$2:$E$48992=$A15)*('HR2to5 - PY data'!$G$2:$G$48992))} -> 0 | K15: =SUM(G15:J15) -> 0 | L15: {=SUMPRODUCT(('HR2to5 - PY data'!$A$2:$A$48992=$C$4)*('HR2to5 - PY data'!$B$2:$B$48992=$D$4)*('HR2to5 - PY data'!$C$2:$C$48992=$E$4)*('HR2to5 - PY data'!$F$2:$F$48992=L$10)*('HR2to5 - PY data'!$E$2:$E$48992=$A15)*('HR2to5 - PY data'!$G$2:$G$48992))} -> 0 | M15: {=SUMPRODUCT(('HR2to5 - PY data'!$A$2:$A$48992=$C$4)*('HR2to5 - PY data'!$B$2:$B$48992=$D$4)*('HR2to5 - PY data'!$C$2:$C$48992=$E$4)*('HR2to5 - PY data'!$F$2:$F$48992=M$10)*('HR2to5 - PY data'!$E$2:$E$48992=$A15)*('HR2to5 - PY data'!$G$2:$G$48992))} -> 0 | N15: {=SUMPRODUCT(('HR2to5 - PY data'!$A$2:$A$48992=$C$4)*('HR2to5 - PY data'!$B$2:$B$48992=$D$4)*('HR2to5 - PY data'!$C$2:$C$48992=$E$4)*('HR2to5 - PY data'!$F$2:$F$48992=N$10)*('HR2to5 - PY data'!$E$2:$E$48992=$A15)*('HR2to5 - PY data'!$G$2:$G$48992))} -> 0 | O15: {=SUMPRODUCT(('HR2to5 - PY data'!$A$2:$A$48992=$C$4)*('HR2to5 - PY data'!$B$2:$B$48992=$D$4)*('HR2to5 - PY data'!$C$2:$C$48992=$E$4)*('HR2to5 - PY data'!$F$2:$F$48992=O$10)*('HR2to5 - PY data'!$E$2:$E$48992=$A15)*('HR2to5 - PY data'!$G$2:$G$48992))} -> 0 | P15: =SUM(L15:O15) -> 0 | Q15: {=SUMPRODUCT(('HR2to5 - PY data'!$A$2:$A$48992=$C$4)*('HR2to5 - PY data'!$B$2:$B$48992=$D$4)*('HR2to5 - PY data'!$C$2:$C$48992=$E$4)*('HR2to5 - PY data'!$F$2:$F$48992=Q$10)*('HR2to5 - PY data'!$E$2:$E$48992=$A15)*('HR2to5 - PY data'!$G$2:$G$48992))} -> 0 | R15: {=SUMPRODUCT(('HR2to5 - PY data'!$A$2:$A$48992=$C$4)*('HR2to5 - PY data'!$B$2:$B$48992=$D$4)*('HR2to5 - PY data'!$C$2:$C$48992=$E$4)*('HR2to5 - PY data'!$F$2:$F$48992=R$10)*('HR2to5 - PY data'!$E$2:$E$48992=$A15)*('HR2to5 - PY data'!$G$2:$G$48992))} -> 0 | S15: {=SUMPRODUCT(('HR2to5 - PY data'!$A$2:$A$48992=$C$4)*('HR2to5 - PY data'!$B$2:$B$48992=$D$4)*('HR2to5 - PY data'!$C$2:$C$48992=$E$4)*('HR2to5 - PY data'!$F$2:$F$48992=S$10)*('HR2to5 - PY data'!$E$2:$E$48992=$A15)*('HR2to5 - PY data'!$G$2:$G$48992))} -> 0 | T15: {=SUMPRODUCT(('HR2to5 - PY data'!$A$2:$A$48992=$C$4)*('HR2to5 - PY data'!$B$2:$B$48992=$D$4)*('HR2to5 - PY data'!$C$2:$C$48992=$E$4)*('HR2to5 - PY data'!$F$2:$F$48992=T$10)*('HR2to5 - PY data'!$E$2:$E$48992=$A15)*('HR2to5 - PY data'!$G$2:$G$48992))} -> 0 | U15: =SUM(Q15:T15) -> 0
A16: Crew Manager | B16: {=SUMPRODUCT(('HR2to5 - PY data'!$A$2:$A$48992=$C$4)*('HR2to5 - PY data'!$B$2:$B$48992=$D$4)*('HR2to5 - PY data'!$C$2:$C$48992=$E$4)*('HR2to5 - PY data'!$F$2:$F$48992=B$10)*('HR2to5 - PY data'!$E$2:$E$48992=$A16)*('HR2to5 - PY data'!$G$2:$G$48992))} -> 0 | C16: {=SUMPRODUCT(('HR2to5 - PY data'!$A$2:$A$48992=$C$4)*('HR2to5 - PY data'!$B$2:$B$48992=$D$4)*('HR2to5 - PY data'!$C$2:$C$48992=$E$4)*('HR2to5 - PY data'!$F$2:$F$48992=C$10)*('HR2to5 - PY data'!$E$2:$E$48992=$A16)*('HR2to5 - PY data'!$G$2:$G$48992))} -> 0 | D16: {=SUMPRODUCT(('HR2to5 - PY data'!$A$2:$A$48992=$C$4)*('HR2to5 - PY data'!$B$2:$B$48992=$D$4)*('HR2to5 - PY data'!$C$2:$C$48992=$E$4)*('HR2to5 - PY data'!$F$2:$F$48992=D$10)*('HR2to5 - PY data'!$E$2:$E$48992=$A16)*('HR2to5 - PY data'!$G$2:$G$48992))} -> 0 | E16: {=SUMPRODUCT(('HR2to5 - PY data'!$A$2:$A$48992=$C$4)*('HR2to5 - PY data'!$B$2:$B$48992=$D$4)*('HR2to5 - PY data'!$C$2:$C$48992=$E$4)*('HR2to5 - PY data'!$F$2:$F$48992=E$10)*('HR2to5 - PY data'!$E$2:$E$48992=$A16)*('HR2to5 - PY data'!$G$2:$G$48992))} -> 0 | F16: =SUM(B16:E16) -> 0 | G16: {=SUMPRODUCT(('HR2to5 - PY data'!$A$2:$A$48992=$C$4)*('HR2to5 - PY data'!$B$2:$B$48992=$D$4)*('HR2to5 - PY data'!$C$2:$C$48992=$E$4)*('HR2to5 - PY data'!$F$2:$F$48992=G$10)*('HR2to5 - PY data'!$E$2:$E$48992=$A16)*('HR2to5 - PY data'!$G$2:$G$48992))} -> 0 | H16: {=SUMPRODUCT(('HR2to5 - PY data'!$A$2:$A$48992=$C$4)*('HR2to5 - PY data'!$B$2:$B$48992=$D$4)*('HR2to5 - PY data'!$C$2:$C$48992=$E$4)*('HR2to5 - PY data'!$F$2:$F$48992=H$10)*('HR2to5 - PY data'!$E$2:$E$48992=$A16)*('HR2to5 - PY data'!$G$2:$G$48992))} -> 0 | I16: {=SUMPRODUCT(('HR2to5 - PY data'!$A$2:$A$48992=$C$4)*('HR2to5 - PY data'!$B$2:$B$48992=$D$4)*('HR2to5 - PY data'!$C$2:$C$48992=$E$4)*('HR2to5 - PY data'!$F$2:$F$48992=I$10)*('HR2to5 - PY data'!$E$2:$E$48992=$A16)*('HR2to5 - PY data'!$G$2:$G$48992))} -> 0 | J16: {=SUMPRODUCT(('HR2to5 - PY data'!$A$2:$A$48992=$C$4)*('HR2to5 - PY data'!$B$2:$B$48992=$D$4)*('HR2to5 - PY data'!$C$2:$C$48992=$E$4)*('HR2to5 - PY data'!$F$2:$F$48992=J$10)*('HR2to5 - PY data'!$E$2:$E$48992=$A16)*('HR2to5 - PY data'!$G$2:$G$48992))} -> 0 | K16: =SUM(G16:J16) -> 0 | L16: {=SUMPRODUCT(('HR2to5 - PY data'!$A$2:$A$48992=$C$4)*('HR2to5 - PY data'!$B$2:$B$48992=$D$4)*('HR2to5 - PY data'!$C$2:$C$48992=$E$4)*('HR2to5 - PY data'!$F$2:$F$48992=L$10)*('HR2to5 - PY data'!$E$2:$E$48992=$A16)*('HR2to5 - PY data'!$G$2:$G$48992))} -> 0 | M16: {=SUMPRODUCT(('HR2to5 - PY data'!$A$2:$A$48992=$C$4)*('HR2to5 - PY data'!$B$2:$B$48992=$D$4)*('HR2to5 - PY data'!$C$2:$C$48992=$E$4)*('HR2to5 - PY data'!$F$2:$F$48992=M$10)*('HR2to5 - PY data'!$E$2:$E$48992=$A16)*('HR2to5 - PY data'!$G$2:$G$48992))} -> 0 | N16: {=SUMPRODUCT(('HR2to5 - PY data'!$A$2:$A$48992=$C$4)*('HR2to5 - PY data'!$B$2:$B$48992=$D$4)*('HR2to5 - PY data'!$C$2:$C$48992=$E$4)*('HR2to5 - PY data'!$F$2:$F$48992=N$10)*('HR2to5 - PY data'!$E$2:$E$48992=$A16)*('HR2to5 - PY data'!$G$2:$G$48992))} -> 0 | O16: {=SUMPRODUCT(('HR2to5 - PY data'!$A$2:$A$48992=$C$4)*('HR2to5 - PY data'!$B$2:$B$48992=$D$4)*('HR2to5 - PY data'!$C$2:$C$48992=$E$4)*('HR2to5 - PY data'!$F$2:$F$48992=O$10)*('HR2to5 - PY data'!$E$2:$E$48992=$A16)*('HR2to5 - PY data'!$G$2:$G$48992))} -> 0 | P16: =SUM(L16:O16) -> 0 | Q16: {=SUMPRODUCT(('HR2to5 - PY data'!$A$2:$A$48992=$C$4)*('HR2to5 - PY data'!$B$2:$B$48992=$D$4)*('HR2to5 - PY data'!$C$2:$C$48992=$E$4)*('HR2to5 - PY data'!$F$2:$F$48992=Q$10)*('HR2to5 - PY data'!$E$2:$E$48992=$A16)*('HR2to5 - PY data'!$G$2:$G$48992))} -> 0 | R16: {=SUMPRODUCT(('HR2to5 - PY data'!$A$2:$A$48992=$C$4)*('HR2to5 - PY data'!$B$2:$B$48992=$D$4)*('HR2to5 - PY data'!$C$2:$C$48992=$E$4)*('HR2to5 - PY data'!$F$2:$F$48992=R$10)*('HR2to5 - PY data'!$E$2:$E$48992=$A16)*('HR2to5 - PY data'!$G$2:$G$48992))} -> 0 | S16: {=SUMPRODUCT(('HR2to5 - PY data'!$A$2:$A$48992=$C$4)*('HR2to5 - PY data'!$B$2:$B$48992=$D$4)*('HR2to5 - PY data'!$C$2:$C$48992=$E$4)*('HR2to5 - PY data'!$F$2:$F$48992=S$10)*('HR2to5 - PY data'!$E$2:$E$48992=$A16)*('HR2to5 - PY data'!$G$2:$G$48992))} -> 0 | T16: {=SUMPRODUCT(('HR2to5 - PY data'!$A$2:$A$48992=$C$4)*('HR2to5 - PY data'!$B$2:$B$48992=$D$4)*('HR2to5 - PY data'!$C$2:$C$48992=$E$4)*('HR2to5 - PY data'!$F$2:$F$48992=T$10)*('HR2to5 - PY data'!$E$2:$E$48992=$A16)*('HR2to5 - PY data'!$G$2:$G$48992))} -> 0 | U16: =SUM(Q16:T16) -> 0
A17: Firefighter | B17: {=SUMPRODUCT(('HR2to5 - PY data'!$A$2:$A$48992=$C$4)*('HR2to5 - PY data'!$B$2:$B$48992=$D$4)*('HR2to5 - PY data'!$C$2:$C$48992=$E$4)*('HR2to5 - PY data'!$F$2:$F$48992=B$10)*('HR2to5 - PY data'!$E$2:$E$48992=$A17)*('HR2to5 - PY data'!$G$2:$G$48992))} -> 0 | C17: {=SUMPRODUCT(('HR2to5 - PY data'!$A$2:$A$48992=$C$4)*('HR2to5 - PY data'!$B$2:$B$48992=$D$4)*('HR2to5 - PY data'!$C$2:$C$48992=$E$4)*('HR2to5 - PY data'!$F$2:$F$48992=C$10)*('HR2to5 - PY data'!$E$2:$E$48992=$A17)*('HR2to5 - PY data'!$G$2:$G$48992))} -> 0 | D17: {=SUMPRODUCT(('HR2to5 - PY data'!$A$2:$A$48992=$C$4)*('HR2to5 - PY data'!$B$2:$B$48992=$D$4)*('HR2to5 - PY data'!$C$2:$C$48992=$E$4)*('HR2to5 - PY data'!$F$2:$F$48992=D$10)*('HR2to5 - PY data'!$E$2:$E$48992=$A17)*('HR2to5 - PY data'!$G$2:$G$48992))} -> 0 | E17: {=SUMPRODUCT(('HR2to5 - PY data'!$A$2:$A$48992=$C$4)*('HR2to5 - PY data'!$B$2:$B$48992=$D$4)*('HR2to5 - PY data'!$C$2:$C$48992=$E$4)*('HR2to5 - PY data'!$F$2:$F$48992=E$10)*('HR2to5 - PY data'!$E$2:$E$48992=$A17)*('HR2to5 - PY data'!$G$2:$G$48992))} -> 0 | F17: =SUM(B17:E17) -> 0 | G17: {=SUMPRODUCT(('HR2to5 - PY data'!$A$2:$A$48992=$C$4)*('HR2to5 - PY data'!$B$2:$B$48992=$D$4)*('HR2to5 - PY data'!$C$2:$C$48992=$E$4)*('HR2to5 - PY data'!$F$2:$F$48992=G$10)*('HR2to5 - PY data'!$E$2:$E$48992=$A17)*('HR2to5 - PY data'!$G$2:$G$48992))} -> 0 | H17: {=SUMPRODUCT(('HR2to5 - PY data'!$A$2:$A$48992=$C$4)*('HR2to5 - PY data'!$B$2:$B$48992=$D$4)*('HR2to5 - PY data'!$C$2:$C$48992=$E$4)*('HR2to5 - PY data'!$F$2:$F$48992=H$10)*('HR2to5 - PY data'!$E$2:$E$48992=$A17)*('HR2to5 - PY data'!$G$2:$G$48992))} -> 0 | I17: {=SUMPRODUCT(('HR2to5 - PY data'!$A$2:$A$48992=$C$4)*('HR2to5 - PY data'!$B$2:$B$48992=$D$4)*('HR2to5 - PY data'!$C$2:$C$48992=$E$4)*('HR2to5 - PY data'!$F$2:$F$48992=I$10)*('HR2to5 - PY data'!$E$2:$E$48992=$A17)*('HR2to5 - PY data'!$G$2:$G$48992))} -> 0 | J17: {=SUMPRODUCT(('HR2to5 - PY data'!$A$2:$A$48992=$C$4)*('HR2to5 - PY data'!$B$2:$B$48992=$D$4)*('HR2to5 - PY data'!$C$2:$C$48992=$E$4)*('HR2to5 - PY data'!$F$2:$F$48992=J$10)*('HR2to5 - PY data'!$E$2:$E$48992=$A17)*('HR2to5 - PY data'!$G$2:$G$48992))} -> 0 | K17: =SUM(G17:J17) -> 0 | L17: {=SUMPRODUCT(('HR2to5 - PY data'!$A$2:$A$48992=$C$4)*('HR2to5 - PY data'!$B$2:$B$48992=$D$4)*('HR2to5 - PY data'!$C$2:$C$48992=$E$4)*('HR2to5 - PY data'!$F$2:$F$48992=L$10)*('HR2to5 - PY data'!$E$2:$E$48992=$A17)*('HR2to5 - PY data'!$G$2:$G$48992))} -> 0 | M17: {=SUMPRODUCT(('HR2to5 - PY data'!$A$2:$A$48992=$C$4)*('HR2to5 - PY data'!$B$2:$B$48992=$D$4)*('HR2to5 - PY data'!$C$2:$C$48992=$E$4)*('HR2to5 - PY data'!$F$2:$F$48992=M$10)*('HR2to5 - PY data'!$E$2:$E$48992=$A17)*('HR2to5 - PY data'!$G$2:$G$48992))} -> 0 | N17: {=SUMPRODUCT(('HR2to5 - PY data'!$A$2:$A$48992=$C$4)*('HR2to5 - PY data'!$B$2:$B$48992=$D$4)*('HR2to5 - PY data'!$C$2:$C$48992=$E$4)*('HR2to5 - PY data'!$F$2:$F$48992=N$10)*('HR2to5 - PY data'!$E$2:$E$48992=$A17)*('HR2to5 - PY data'!$G$2:$G$48992))} -> 0 | O17: {=SUMPRODUCT(('HR2to5 - PY data'!$A$2:$A$48992=$C$4)*('HR2to5 - PY data'!$B$2:$B$48992=$D$4)*('HR2to5 - PY data'!$C$2:$C$48992=$E$4)*('HR2to5 - PY data'!$F$2:$F$48992=O$10)*('HR2to5 - PY data'!$E$2:$E$48992=$A17)*('HR2to5 - PY data'!$G$2:$G$48992))} -> 0 | P17: =SUM(L17:O17) -> 0 | Q17: {=SUMPRODUCT(('HR2to5 - PY data'!$A$2:$A$48992=$C$4)*('HR2to5 - PY data'!$B$2:$B$48992=$D$4)*('HR2to5 - PY data'!$C$2:$C$48992=$E$4)*('HR2to5 - PY data'!$F$2:$F$48992=Q$10)*('HR2to5 - PY data'!$E$2:$E$48992=$A17)*('HR2to5 - PY data'!$G$2:$G$48992))} -> 0 | R17: {=SUMPRODUCT(('HR2to5 - PY data'!$A$2:$A$48992=$C$4)*('HR2to5 - PY data'!$B$2:$B$48992=$D$4)*('HR2to5 - PY data'!$C$2:$C$48992=$E$4)*('HR2to5 - PY data'!$F$2:$F$48992=R$10)*('HR2to5 - PY data'!$E$2:$E$48992=$A17)*('HR2to5 - PY data'!$G$2:$G$48992))} -> 0 | S17: {=SUMPRODUCT(('HR2to5 - PY data'!$A$2:$A$48992=$C$4)*('HR2to5 - PY data'!$B$2:$B$48992=$D$4)*('HR2to5 - PY data'!$C$2:$C$48992=$E$4)*('HR2to5 - PY data'!$F$2:$F$48992=S$10)*('HR2to5 - PY data'!$E$2:$E$48992=$A17)*('HR2to5 - PY data'!$G$2:$G$48992))} -> 0 | T17: {=SUMPRODUCT(('HR2to5 - PY data'!$A$2:$A$48992=$C$4)*('HR2to5 - PY data'!$B$2:$B$48992=$D$4)*('HR2to5 - PY data'!$C$2:$C$48992=$E$4)*('HR2to5 - PY data'!$F$2:$F$48992=T$10)*('HR2to5 - PY data'!$E$2:$E$48992=$A17)*('HR2to5 - PY data'!$G$2:$G$48992))} -> 0 | U17: =SUM(Q17:T17) -> 0
A18: Total | B18: =SUM(B11:B17) -> 0 | C18: =SUM(C11:C17) -> 0 | D18: =SUM(D11:D17) -> 0 | E18: =SUM(E11:E17) -> 0 | F18: =SUM(F11:F17) -> 0 | G18: =SUM(G11:G17) -> 0 | H18: =SUM(H11:H17) -> 0 | I18: =SUM(I11:I17) -> 0 | ... U18: =SUM(U11:U17) -> 0
B22: Men_56to65 | C22: Women_56to65 | D22: Other_56to65 | E22: Unknown_56to65 | F22: Total | G22: Men_66plus | H22: Women_66plus | I22: Other_66plus | J22: Unknown_66plus | K22: Total | L22: Men_age_not_stated | M22: Women_age_not_stated | N22: Other_age_not_stated | O22: Unknown_age_not_stated | P22: Total | Q22: Men | R22: Women | S22: Other | T22: Unknown | U22: Total
A23: Brigade Manager | B23: {=SUMPRODUCT(('HR2to5 - PY data'!$A$2:$A$48992=$C$4)*('HR2to5 - PY data'!$B$2:$B$48992=$D$4)*('HR2to5 - PY data'!$C$2:$C$48992=$E$4)*('HR2to5 - PY data'!$F$2:$F$48992=B$22)*('HR2to5 - PY data'!$E$2:$E$48992=$A23)*('HR2to5 - PY data'!$G$2:$G$48992))} -> 0 | C23: {=SUMPRODUCT(('HR2to5 - PY data'!$A$2:$A$48992=$C$4)*('HR2to5 - PY data'!$B$2:$B$48992=$D$4)*('HR2to5 - PY data'!$C$2:$C$48992=$E$4)*('HR2to5 - PY data'!$F$2:$F$48992=C$22)*('HR2to5 - PY data'!$E$2:$E$48992=$A23)*('HR2to5 - PY data'!$G$2:$G$48992))} -> 0 | D23: {=SUMPRODUCT(('HR2to5 - PY data'!$A$2:$A$48992=$C$4)*('HR2to5 - PY data'!$B$2:$B$48992=$D$4)*('HR2to5 - PY data'!$C$2:$C$48992=$E$4)*('HR2to5 - PY data'!$F$2:$F$48992=D$22)*('HR2to5 - PY data'!$E$2:$E$48992=$A23)*('HR2to5 - PY data'!$G$2:$G$48992))} -> 0 | E23: {=SUMPRODUCT(('HR2to5 - PY data'!$A$2:$A$48992=$C$4)*('HR2to5 - PY data'!$B$2:$B$48992=$D$4)*('HR2to5 - PY data'!$C$2:$C$48992=$E$4)*('HR2to5 - PY data'!$F$2:$F$48992=E$22)*('HR2to5 - PY data'!$E$2:$E$48992=$A23)*('HR2to5 - PY data'!$G$2:$G$48992))} -> 0 | F23: =SUM(B23:E23) -> 0 | G23: {=SUMPRODUCT(('HR2to5 - PY data'!$A$2:$A$48992=$C$4)*('HR2to5 - PY data'!$B$2:$B$48992=$D$4)*('HR2to5 - PY data'!$C$2:$C$48992=$E$4)*('HR2to5 - PY data'!$F$2:$F$48992=G$22)*('HR2to5 - PY data'!$E$2:$E$48992=$A23)*('HR2to5 - PY data'!$G$2:$G$48992))} -> 0 | H23: {=SUMPRODUCT(('HR2to5 - PY data'!$A$2:$A$48992=$C$4)*('HR2to5 - PY data'!$B$2:$B$48992=$D$4)*('HR2to5 - PY data'!$C$2:$C$48992=$E$4)*('HR2to5 - PY data'!$F$2:$F$48992=H$22)*('HR2to5 - PY data'!$E$2:$E$48992=$A23)*('HR2to5 - PY data'!$G$2:$G$48992))} -> 0 | I23: {=SUMPRODUCT(('HR2to5 - PY data'!$A$2:$A$48992=$C$4)*('HR2to5 - PY data'!$B$2:$B$48992=$D$4)*('HR2to5 - PY data'!$C$2:$C$48992=$E$4)*('HR2to5 - PY data'!$F$2:$F$48992=I$22)*('HR2to5 - PY data'!$E$2:$E$48992=$A23)*('HR2to5 - PY data'!$G$2:$G$48992))} -> 0 | J23: {=SUMPRODUCT(('HR2to5 - PY data'!$A$2:$A$48992=$C$4)*('HR2to5 - PY data'!$B$2:$B$48992=$D$4)*('HR2to5 - PY data'!$C$2:$C$48992=$E$4)*('HR2to5 - PY data'!$F$2:$F$48992=J$22)*('HR2to5 - PY data'!$E$2:$E$48992=$A23)*('HR2to5 - PY data'!$G$2:$G$48992))} -> 0 | K23: =SUM(G23:J23) -> 0 | L23: {=SUMPRODUCT(('HR2to5 - PY data'!$A$2:$A$48992=$C$4)*('HR2to5 - PY data'!$B$2:$B$48992=$D$4)*('HR2to5 - PY data'!$C$2:$C$48992=$E$4)*('HR2to5 - PY data'!$F$2:$F$48992=L$22)*('HR2to5 - PY data'!$E$2:$E$48992=$A23)*('HR2to5 - PY data'!$G$2:$G$48992))} -> 0 | M23: {=SUMPRODUCT(('HR2to5 - PY data'!$A$2:$A$48992=$C$4)*('HR2to5 - PY data'!$B$2:$B$48992=$D$4)*('HR2to5 - PY data'!$C$2:$C$48992=$E$4)*('HR2to5 - PY data'!$F$2:$F$48992=M$22)*('HR2to5 - PY data'!$E$2:$E$48992=$A23)*('HR2to5 - PY data'!$G$2:$G$48992))} -> 0 | N23: {=SUMPRODUCT(('HR2to5 - PY data'!$A$2:$A$48992=$C$4)*('HR2to5 - PY data'!$B$2:$B$48992=$D$4)*('HR2to5 - PY data'!$C$2:$C$48992=$E$4)*('HR2to5 - PY data'!$F$2:$F$48992=N$22)*('HR2to5 - PY data'!$E$2:$E$48992=$A23)*('HR2to5 - PY data'!$G$2:$G$48992))} -> 0 | O23: {=SUMPRODUCT(('HR2to5 - PY data'!$A$2:$A$48992=$C$4)*('HR2to5 - PY data'!$B$2:$B$48992=$D$4)*('HR2to5 - PY data'!$C$2:$C$48992=$E$4)*('HR2to5 - PY data'!$F$2:$F$48992=O$22)*('HR2to5 - PY data'!$E$2:$E$48992=$A23)*('HR2to5 - PY data'!$G$2:$G$48992))} -> 0 | P23: =SUM(L23:O23) -> 0 | Q23: =B11+G11+L11+Q11+B23+G23+L23 -> 0 | R23: =C11+H11+M11+R11+C23+H23+M23 -> 0 | S23: =D11+I11+N11+S11+D23+I23+N23 -> 0 | T23: =E11+J11+O11+T11+E23+J23+O23 -> 0 | U23: =F11+K11+P11+U11+F23+K23+P23 -> 0
A24: Area Manager | B24: {=SUMPRODUCT(('HR2to5 - PY data'!$A$2:$A$48992=$C$4)*('HR2to5 - PY data'!$B$2:$B$48992=$D$4)*('HR2to5 - PY data'!$C$2:$C$48992=$E$4)*('HR2to5 - PY data'!$F$2:$F$48992=B$22)*('HR2to5 - PY data'!$E$2:$E$48992=$A24)*('HR2to5 - PY data'!$G$2:$G$48992))} -> 0 | C24: {=SUMPRODUCT(('HR2to5 - PY data'!$A$2:$A$48992=$C$4)*('HR2to5 - PY data'!$B$2:$B$48992=$D$4)*('HR2to5 - PY data'!$C$2:$C$48992=$E$4)*('HR2to5 - PY data'!$F$2:$F$48992=C$22)*('HR2to5 - PY data'!$E$2:$E$48992=$A24)*('HR2to5 - PY data'!$G$2:$G$48992))} -> 0 | D24: {=SUMPRODUCT(('HR2to5 - PY data'!$A$2:$A$48992=$C$4)*('HR2to5 - PY data'!$B$2:$B$48992=$D$4)*('HR2to5 - PY data'!$C$2:$C$48992=$E$4)*('HR2to5 - PY data'!$F$2:$F$48992=D$22)*('HR2to5 - PY data'!$E$2:$E$48992=$A24)*('HR2to5 - PY data'!$G$2:$G$48992))} -> 0 | E24: {=SUMPRODUCT(('HR2to5 - PY data'!$A$2:$A$48992=$C$4)*('HR2to5 - PY data'!$B$2:$B$48992=$D$4)*('HR2to5 - PY data'!$C$2:$C$48992=$E$4)*('HR2to5 - PY data'!$F$2:$F$48992=E$22)*('HR2to5 - PY data'!$E$2:$E$48992=$A24)*('HR2to5 - PY data'!$G$2:$G$48992))} -> 0 | F24: =SUM(B24:E24) -> 0 | G24: {=SUMPRODUCT(('HR2to5 - PY data'!$A$2:$A$48992=$C$4)*('HR2to5 - PY data'!$B$2:$B$48992=$D$4)*('HR2to5 - PY data'!$C$2:$C$48992=$E$4)*('HR2to5 - PY data'!$F$2:$F$48992=G$22)*('HR2to5 - PY data'!$E$2:$E$48992=$A24)*('HR2to5 - PY data'!$G$2:$G$48992))} -> 0 | H24: {=SUMPRODUCT(('HR2to5 - PY data'!$A$2:$A$48992=$C$4)*('HR2to5 - PY data'!$B$2:$B$48992=$D$4)*('HR2to5 - PY data'!$C$2:$C$48992=$E$4)*('HR2to5 - PY data'!$F$2:$F$48992=H$22)*('HR2to5 - PY data'!$E$2:$E$48992=$A24)*('HR2to5 - PY data'!$G$2:$G$48992))} -> 0 | I24: {=SUMPRODUCT(('HR2to5 - PY data'!$A$2:$A$48992=$C$4)*('HR2to5 - PY data'!$B$2:$B$48992=$D$4)*('HR2to5 - PY data'!$C$2:$C$48992=$E$4)*('HR2to5 - PY data'!$F$2:$F$48992=I$22)*('HR2to5 - PY data'!$E$2:$E$48992=$A24)*('HR2to5 - PY data'!$G$2:$G$48992))} -> 0 | J24: {=SUMPRODUCT(('HR2to5 - PY data'!$A$2:$A$48992=$C$4)*('HR2to5 - PY data'!$B$2:$B$48992=$D$4)*('HR2to5 - PY data'!$C$2:$C$48992=$E$4)*('HR2to5 - PY data'!$F$2:$F$48992=J$22)*('HR2to5 - PY data'!$E$2:$E$48992=$A24)*('HR2to5 - PY data'!$G$2:$G$48992))} -> 0 | K24: =SUM(G24:J24) -> 0 | L24: {=SUMPRODUCT(('HR2to5 - PY data'!$A$2:$A$48992=$C$4)*('HR2to5 - PY data'!$B$2:$B$48992=$D$4)*('HR2to5 - PY data'!$C$2:$C$48992=$E$4)*('HR2to5 - PY data'!$F$2:$F$48992=L$22)*('HR2to5 - PY data'!$E$2:$E$48992=$A24)*('HR2to5 - PY data'!$G$2:$G$48992))} -> 0 | M24: {=SUMPRODUCT(('HR2to5 - PY data'!$A$2:$A$48992=$C$4)*('HR2to5 - PY data'!$B$2:$B$48992=$D$4)*('HR2to5 - PY data'!$C$2:$C$48992=$E$4)*('HR2to5 - PY data'!$F$2:$F$48992=M$22)*('HR2to5 - PY data'!$E$2:$E$48992=$A24)*('HR2to5 - PY data'!$G$2:$G$48992))} -> 0 | N24: {=SUMPRODUCT(('HR2to5 - PY data'!$A$2:$A$48992=$C$4)*('HR2to5 - PY data'!$B$2:$B$48992=$D$4)*('HR2to5 - PY data'!$C$2:$C$48992=$E$4)*('HR2to5 - PY data'!$F$2:$F$48992=N$22)*('HR2to5 - PY data'!$E$2:$E$48992=$A24)*('HR2to5 - PY data'!$G$2:$G$48992))} -> 0 | O24: {=SUMPRODUCT(('HR2to5 - PY data'!$A$2:$A$48992=$C$4)*('HR2to5 - PY data'!$B$2:$B$48992=$D$4)*('HR2to5 - PY data'!$C$2:$C$48992=$E$4)*('HR2to5 - PY data'!$F$2:$F$48992=O$22)*('HR2to5 - PY data'!$E$2:$E$48992=$A24)*('HR2to5 - PY data'!$G$2:$G$48992))} -> 0 | P24: =SUM(L24:O24) -> 0 | Q24: =B12+G12+L12+Q12+B24+G24+L24 -> 0 | R24: =C12+H12+M12+R12+C24+H24+M24 -> 0 | S24: =D12+I12+N12+S12+D24+I24+N24 -> 0 | T24: =E12+J12+O12+T12+E24+J24+O24 -> 0 | U24: =F12+K12+P12+U12+F24+K24+P24 -> 0
A25: Group Manager | B25: {=SUMPRODUCT(('HR2to5 - PY data'!$A$2:$A$48992=$C$4)*('HR2to5 - PY data'!$B$2:$B$48992=$D$4)*('HR2to5 - PY data'!$C$2:$C$48992=$E$4)*('HR2to5 - PY data'!$F$2:$F$48992=B$22)*('HR2to5 - PY data'!$E$2:$E$48992=$A25)*('HR2to5 - PY data'!$G$2:$G$48992))} -> 0 | C25: {=SUMPRODUCT(('HR2to5 - PY data'!$A$2:$A$48992=$C$4)*('HR2to5 - PY data'!$B$2:$B$48992=$D$4)*('HR2to5 - PY data'!$C$2:$C$48992=$E$4)*('HR2to5 - PY data'!$F$2:$F$48992=C$22)*('HR2to5 - PY data'!$E$2:$E$48992=$A25)*('HR2to5 - PY data'!$G$2:$G$48992))} -> 0 | D25: {=SUMPRODUCT(('HR2to5 - PY data'!$A$2:$A$48992=$C$4)*('HR2to5 - PY data'!$B$2:$B$48992=$D$4)*('HR2to5 - PY data'!$C$2:$C$48992=$E$4)*('HR2to5 - PY data'!$F$2:$F$48992=D$22)*('HR2to5 - PY data'!$E$2:$E$48992=$A25)*('HR2to5 - PY data'!$G$2:$G$48992))} -> 0 | E25: {=SUMPRODUCT(('HR2to5 - PY data'!$A$2:$A$48992=$C$4)*('HR2to5 - PY data'!$B$2:$B$48992=$D$4)*('HR2to5 - PY data'!$C$2:$C$48992=$E$4)*('HR2to5 - PY data'!$F$2:$F$48992=E$22)*('HR2to5 - PY data'!$E$2:$E$48992=$A25)*('HR2to5 - PY data'!$G$2:$G$48992))} -> 0 | F25: =SUM(B25:E25) -> 0 | G25: {=SUMPRODUCT(('HR2to5 - PY data'!$A$2:$A$48992=$C$4)*('HR2to5 - PY data'!$B$2:$B$48992=$D$4)*('HR2to5 - PY data'!$C$2:$C$48992=$E$4)*('HR2to5 - PY data'!$F$2:$F$48992=G$22)*('HR2to5 - PY data'!$E$2:$E$48992=$A25)*('HR2to5 - PY data'!$G$2:$G$48992))} -> 0 | H25: {=SUMPRODUCT(('HR2to5 - PY data'!$A$2:$A$48992=$C$4)*('HR2to5 - PY data'!$B$2:$B$48992=$D$4)*('HR2to5 - PY data'!$C$2:$C$48992=$E$4)*('HR2to5 - PY data'!$F$2:$F$48992=H$22)*('HR2to5 - PY data'!$E$2:$E$48992=$A25)*('HR2to5 - PY data'!$G$2:$G$48992))} -> 0 | I25: {=SUMPRODUCT(('HR2to5 - PY data'!$A$2:$A$48992=$C$4)*('HR2to5 - PY data'!$B$2:$B$48992=$D$4)*('HR2to5 - PY data'!$C$2:$C$48992=$E$4)*('HR2to5 - PY data'!$F$2:$F$48992=I$22)*('HR2to5 - PY data'!$E$2:$E$48992=$A25)*('HR2to5 - PY data'!$G$2:$G$48992))} -> 0 | J25: {=SUMPRODUCT(('HR2to5 - PY data'!$A$2:$A$48992=$C$4)*('HR2to5 - PY data'!$B$2:$B$48992=$D$4)*('HR2to5 - PY data'!$C$2:$C$48992=$E$4)*('HR2to5 - PY data'!$F$2:$F$48992=J$22)*('HR2to5 - PY data'!$E$2:$E$48992=$A25)*('HR2to5 - PY data'!$G$2:$G$48992))} -> 0 | K25: =SUM(G25:J25) -> 0 | L25: {=SUMPRODUCT(('HR2to5 - PY data'!$A$2:$A$48992=$C$4)*('HR2to5 - PY data'!$B$2:$B$48992=$D$4)*('HR2to5 - PY data'!$C$2:$C$48992=$E$4)*('HR2to5 - PY data'!$F$2:$F$48992=L$22)*('HR2to5 - PY data'!$E$2:$E$48992=$A25)*('HR2to5 - PY data'!$G$2:$G$48992))} -> 0 | M25: {=SUMPRODUCT(('HR2to5 - PY data'!$A$2:$A$48992=$C$4)*('HR2to5 - PY data'!$B$2:$B$48992=$D$4)*('HR2to5 - PY data'!$C$2:$C$48992=$E$4)*('HR2to5 - PY data'!$F$2:$F$48992=M$22)*('HR2to5 - PY data'!$E$2:$E$48992=$A25)*('HR2to5 - PY data'!$G$2:$G$48992))} -> 0 | N25: {=SUMPRODUCT(('HR2to5 - PY data'!$A$2:$A$48992=$C$4)*('HR2to5 - PY data'!$B$2:$B$48992=$D$4)*('HR2to5 - PY data'!$C$2:$C$48992=$E$4)*('HR2to5 - PY data'!$F$2:$F$48992=N$22)*('HR2to5 - PY data'!$E$2:$E$48992=$A25)*('HR2to5 - PY data'!$G$2:$G$48992))} -> 0 | O25: {=SUMPRODUCT(('HR2to5 - PY data'!$A$2:$A$48992=$C$4)*('HR2to5 - PY data'!$B$2:$B$48992=$D$4)*('HR2to5 - PY data'!$C$2:$C$48992=$E$4)*('HR2to5 - PY data'!$F$2:$F$48992=O$22)*('HR2to5 - PY data'!$E$2:$E$48992=$A25)*('HR2to5 - PY data'!$G$2:$G$48992))} -> 0 | P25: =SUM(L25:O25) -> 0 | Q25: =B13+G13+L13+Q13+B25+G25+L25 -> 0 | R25: =C13+H13+M13+R13+C25+H25+M25 -> 0 | S25: =D13+I13+N13+S13+D25+I25+N25 -> 0 | T25: =E13+J13+O13+T13+E25+J25+O25 -> 0 | U25: =F13+K13+P13+U13+F25+K25+P25 -> 0
